<?xml version="1.0" ?>
<sdf version="1.5">
  <model name="f651_brute">
    <static>false</static>
    <pose>0 0 0.35 0 0 0</pose>

<!-- ######################################## BODY # ######################################## -->
    <link name="base_link">
	<gravity>true</gravity>
	<pose>0 0 -0.003 0 0 -1.570</pose>
	
      <inertial>
        <pose frame=''>0.001005 0 -0.0090035 0 -0 0</pose>
        <mass>2.0</mass>
        <inertia>
          <ixx>0.011</ixx>
          <ixy>0</ixy>
          <ixz>0</ixz>
          <iyy>0.015</iyy>
          <iyz>0</iyz>
          <izz>0.021</izz>
        </inertia>
      </inertial>

	<collision name='base_link_collision'>
		<geometry>
			<mesh>
				<scale>0.001 0.001 0.001</scale>
				<uri>model://f651_brute/meshes/f651_brute_body.STL</uri>
			</mesh>
		</geometry>
		<surface>
			<contact>
				<ode>
					<min_depth>0.001</min_depth>						
				</ode>
			</contact>		
			<friction>
				<ode>
					<mu>50</mu>
					<mu2>50</mu2>			
				</ode>
			</friction>			
		</surface>
	</collision>

      <visual name="base_link_visual">
        <geometry>
          <mesh>
            <scale>0.001 0.001 0.001</scale>
            <uri>model://f651_brute/meshes/f651_brute_body.STL</uri>
          </mesh>
        </geometry>
        <material>
          <script>
            <name>Gazebo/DarkGrey</name>
            <uri>file://media/materials/scripts/gazebo.material</uri>
          </script>
        </material>
      </visual>
    </link>
<!-- ####################################### /BODY # ######################################## -->

<!-- ######################################## FRONT_ARMS ############################################ -->
    <link name="FRONT_ARMS_link">
	<gravity>true</gravity>
	<pose>0 0 -0.003 0 0 -1.5708</pose>
	
      <inertial>
        <mass>0.1</mass>
        <inertia>
          <ixx>0.001</ixx>
          <ixy>0</ixy>
          <ixz>0</ixz>
          <iyy>0.001</iyy>
          <iyz>0</iyz>
          <izz>0.001</izz>
        </inertia>
      </inertial>

	<collision name='FRONT_ARMS_collision'>
		<geometry>
			<mesh>
				<scale>0.001 0.001 0.001</scale>
				<uri>model://f651_brute/meshes/f651_brute_front_arms.STL</uri>
			</mesh>
		</geometry>
		<surface>
			<contact>
				<ode>
					<min_depth>0.001</min_depth>						
				</ode>
			</contact>		
			<friction>
				<ode>
					<mu>50</mu>
					<mu2>50</mu2>			
				</ode>
			</friction>			
		</surface>
	</collision>

      <visual name="visual_FRONT_ARMS">
        <geometry>
          <mesh>
            <scale>0.001 0.001 0.001</scale>
            <uri>model://f651_brute/meshes/f651_brute_front_arms.STL</uri>
          </mesh>
        </geometry>
        <material>
          <script>
            <name>Gazebo/White</name>
            <uri>file://media/materials/scripts/gazebo.material</uri>
          </script>
        </material>
      </visual>
    </link>

	<joint name='FRONT_ARMS_joint' type='fixed'>
	  	<child>FRONT_ARMS_link</child>
	  	<parent>base_link</parent>
	</joint>
<!-- ####################################### /FRONT_ARMS ############################################ -->

<!-- ######################################## TX2_TOP_PLATE ############################################ -->
    <link name="TX2_TOP_PLATE_link">
	<gravity>true</gravity>
	<pose>0 0 -0.003 0 0 -1.5708</pose>
	
      <inertial>
        <mass>0.1</mass>
        <inertia>
          <ixx>0.001</ixx>
          <ixy>0</ixy>
          <ixz>0</ixz>
          <iyy>0.001</iyy>
          <iyz>0</iyz>
          <izz>0.001</izz>
        </inertia>
      </inertial>

      <visual name="visual_TX2_TOP_PLATE">
		<transparency>0.7</transparency>
        <geometry>
          <mesh>
            <scale>0.001 0.001 0.001</scale>
            <uri>model://f651_brute/meshes/F651_TX2_Top_Plate.STL</uri>
          </mesh>
        </geometry>
        <material>
          <script>
            <name>Gazebo/White</name>
            <uri>file://media/materials/scripts/gazebo.material</uri>
          </script>
        </material>
      </visual>
    </link>

	<joint name='TX2_TOP_PLATE_joint' type='fixed'>
	  	<child>TX2_TOP_PLATE_link</child>
	  	<parent>base_link</parent>
	</joint>
<!-- ####################################### /FRONT_ARMS ############################################ -->

<!-- ######################################### grip1 ############################################### -->

        <link name="grip1">
            <pose>0.072876141 0.042074822 -0.08910 0 0 -1.0472</pose>
            <inertial>
                <mass>0.01</mass>
                <inertia>
                    <ixx>0.01</ixx>
                    <ixy>0</ixy>
                    <ixz>0</ixz>
                    <iyy>0.01</iyy>
                    <iyz>0</iyz>
                    <izz>0.01</izz>
                </inertia>
            </inertial>

            <collision name="collision_grip1">
				<geometry>
					<mesh>
						<scale>0.001 0.001 0.001</scale>
						<uri>model://f651_brute/meshes/Long_grippers.STL</uri>
					</mesh>
				</geometry>
				<surface>
					<contact>
						<ode>
							<min_depth>0.001</min_depth>						
						</ode>
					</contact>		
					<friction>
						<ode>
							<mu>50</mu>
							<mu2>50</mu2>			
						</ode>
					</friction>			
				</surface>
            </collision>

            <visual name="visual_grip1">
				<geometry>
					<mesh>
						<scale>0.001 0.001 0.001</scale>
						<uri>model://f651_brute/meshes/Long_grippers.STL</uri>
					</mesh>
				</geometry>
				<material>
				  <script>
				    <name>Gazebo/Green</name>
				    <uri>file://media/materials/scripts/gazebo.material</uri>
				  </script>
				</material>
            </visual>
        </link>

        <joint name="joint_grip1" type="revolute">
            <pose>0 0 0 0 0 0</pose>
            <child>grip1</child>
            <parent>base_link</parent>
            <axis>
                <xyz>1 0 0</xyz>
				<limit>
					<lower>-1.570</lower>
					<upper>0.001</upper>
					<velocity>1</velocity>
				</limit>
				<dynamics>
					<damping>5</damping>
					<friction>0.5</friction>
				</dynamics>
			</axis>
			<physics>
				<ode>
					<implicit_spring_damper>1</implicit_spring_damper>'
				</ode>
			</physics>
        </joint>

<!-- ######################################### /grip1 ############################################### -->

<!-- ######################################### grip2 ############################################### -->

        <link name="grip2">
            <pose>-0.072876141 0.042074822 -0.08910 0 0 1.0472</pose>
            <inertial>
                <mass>0.01</mass>
                <inertia>
                    <ixx>0.01</ixx>
                    <ixy>0</ixy>
                    <ixz>0</ixz>
                    <iyy>0.01</iyy>
                    <iyz>0</iyz>
                    <izz>0.01</izz>
                </inertia>
            </inertial>

            <collision name="collision_grip2">
				<geometry>
					<mesh>
						<scale>0.001 0.001 0.001</scale>
						<uri>model://f651_brute/meshes/Long_grippers.STL</uri>
					</mesh>
				</geometry>
				<surface>
					<contact>
						<ode>
							<min_depth>0.001</min_depth>						
						</ode>
					</contact>		
					<friction>
						<ode>
							<mu>50</mu>
							<mu2>50</mu2>			
						</ode>
					</friction>			
				</surface>
            </collision>

            <visual name="visual_grip2">
				<geometry>
					<mesh>
						<scale>0.001 0.001 0.001</scale>
						<uri>model://f651_brute/meshes/Long_grippers.STL</uri>
					</mesh>
				</geometry>
				<material>
				  <script>
				    <name>Gazebo/Green</name>
				    <uri>file://media/materials/scripts/gazebo.material</uri>
				  </script>
				</material>
            </visual>
        </link>

        <joint name="joint_grip2" type="revolute">
            <pose>0 0 0 0 0 0</pose>
            <child>grip2</child>
            <parent>base_link</parent>
            <axis>
                <xyz>1 0 0</xyz>
				<limit>
					<lower>-1.570</lower>
					<upper>0.001</upper>
					<velocity>1</velocity>
				</limit>
				<dynamics>
					<damping>5</damping>
					<friction>0.5</friction>
				</dynamics>
			</axis>
			<physics>
				<ode>
					<implicit_spring_damper>1</implicit_spring_damper>'
				</ode>
			</physics>
        </joint>

<!-- ######################################### /grip2 ############################################### -->

<!-- ######################################### grip3 ############################################### -->

        <link name="grip3">
            <pose>0 -0.08415 -0.08910 0 0 3.14159</pose>
            <inertial>
                <mass>0.01</mass>
                <inertia>
                    <ixx>0.01</ixx>
                    <ixy>0</ixy>
                    <ixz>0</ixz>
                    <iyy>0.01</iyy>
                    <iyz>0</iyz>
                    <izz>0.01</izz>
                </inertia>
            </inertial>

            <collision name="collision_grip3">
				<geometry>
					<mesh>
						<scale>0.001 0.001 0.001</scale>
						<uri>model://f651_brute/meshes/Long_grippers.STL</uri>
					</mesh>
				</geometry>
				<surface>
					<contact>
						<ode>
							<min_depth>0.001</min_depth>						
						</ode>
					</contact>		
					<friction>
						<ode>
							<mu>50</mu>
							<mu2>50</mu2>			
						</ode>
					</friction>			
				</surface>
            </collision>

            <visual name="visual_grip3">
				<geometry>
					<mesh>
						<scale>0.001 0.001 0.001</scale>
						<uri>model://f651_brute/meshes/Long_grippers.STL</uri>
					</mesh>
				</geometry>
				<material>
				  <script>
				    <name>Gazebo/Green</name>
				    <uri>file://media/materials/scripts/gazebo.material</uri>
				  </script>
				</material>
            </visual>
        </link>

        <joint name="joint_grip3" type="revolute">
            <pose>0 0 0 0 0 0</pose>
            <child>grip3</child>
            <parent>base_link</parent>
            <axis>
                <xyz>1 0 0</xyz>
				<limit>
					<lower>-1.570</lower>
					<upper>0.001</upper>
					<velocity>1</velocity>
				</limit>
				<dynamics>
					<damping>5</damping>
					<friction>0.5</friction>
				</dynamics>
			</axis>
			<physics>
				<ode>
					<implicit_spring_damper>1</implicit_spring_damper>'
				</ode>
			</physics>
        </joint>

<!-- ######################################### /grip3 ############################################### -->

<!-- ###################################### GRIPPER PLUGIN ########################################## -->
	<plugin name="hex_gripper_control" filename="libgripper_plugin.so" />
<!-- ###################################### /GRIPPER PLUGIN ######################################### -->

<!-- ##########################################  CAMERA  ########################################### -->
    <link name='camera_down_link'>
      <pose>0 0 -0.11 0 1.57079 3.14159265359</pose>
      
	  <inertial>
        <mass>0.001</mass>
          <inertia>
			<ixx>0.001</ixx>
			<ixy>0</ixy>
			<ixz>0</ixz>
			<iyy>0.001</iyy>
			<iyz>0</iyz>
			<izz>0.001</izz>
          </inertia>
      </inertial>
	  <gravity>1</gravity>
	  <self_collide>0</self_collide>
      <kinematic>0</kinematic>

<!--      
	  <visual name='visual_camera_down'>
		<pose>0 0 0 0 -1.57079 0</pose>        
		<geometry>
          <mesh>
            <scale>0.001 0.001 0.001</scale>
            <uri>model://f651_brute/meshes/oCam-1MGN-U_CG.stl</uri>
          </mesh>
        </geometry>
        <material>
          <script>
            <name>Gazebo/Grey</name>
            <uri>file://media/materials/scripts/gazebo.material</uri>
          </script>
        </material>
      </visual>
-->
     
      <sensor name='camera' type='camera'>
        <always_on>1</always_on>
        <update_rate>30</update_rate>
        <camera name='__default__'>
          <horizontal_fov>1.13446</horizontal_fov>
          <image>
            <width>1280</width>
            <height>720</height>
			<format>R8G8B8</format>
          </image>
          <clip>
            <near>0.1</near>
            <far>100</far>
          </clip>
        </camera>
        <plugin name='camera_plugin' filename='libgazebo_ros_camera.so'>
          <alwaysOn>true</alwaysOn>
          <imageTopicName>image_raw_down</imageTopicName>
          <cameraInfoTopicName>camera_info</cameraInfoTopicName>
          <updateRate>10.0</updateRate>
          <cameraName>uav_camera</cameraName>
          <frameName>f651_brute/robot_camera_down</frameName>
          <CxPrime>640.5</CxPrime>
          <Cx>640.5</Cx>
          <Cy>360.5</Cy>
          <hackBaseline>0</hackBaseline>
          <focalLength>1004.603218</focalLength>
          <distortionK1>0.0</distortionK1>
          <distortionK2>0.0</distortionK2>
          <distortionK3>0.0</distortionK3>
          <distortionT1>0.0</distortionT1>
          <distortionT2>0.0</distortionT2>
          <robotNamespace>/</robotNamespace>
        </plugin>
      </sensor>

    </link>

	<joint name='camera_down_joint' type='fixed'>
        <parent>base_link</parent>
        <child>camera_down_link</child>
	</joint>

<!-- ##########################################  /CAMERA  ########################################## -->

<!-- ########################################  CAMERA 3rd  ######################################### -->
    <link name='camera_3rd_link'>
      <pose>-1.2 0 0.6 0 0.35 0</pose>
      
	  <inertial>
        <mass>0.001</mass>
          <inertia>
			<ixx>0.001</ixx>
			<ixy>0</ixy>
			<ixz>0</ixz>
			<iyy>0.001</iyy>
			<iyz>0</iyz>
			<izz>0.001</izz>
          </inertia>
      </inertial>
	  <gravity>1</gravity>
	  <self_collide>0</self_collide>
      <kinematic>0</kinematic>
     
      <sensor name='camera_3rd' type='camera'>
        <always_on>1</always_on>
        <update_rate>60</update_rate>
        <camera name='__default__'>
          <horizontal_fov>2</horizontal_fov>
          <image>
            <width>1920</width>
            <height>1080</height>
          </image>
          <clip>
            <near>0.1</near>
            <far>100</far>
          </clip>
        </camera>
        <plugin name='camera_plugin_3rd' filename='libgazebo_ros_camera.so'>
          <alwaysOn>true</alwaysOn>
          <imageTopicName>image_raw_down_3rd</imageTopicName>
          <cameraInfoTopicName>camera_info_3rd</cameraInfoTopicName>
          <updateRate>10.0</updateRate>
          <cameraName>uav_camera_3rd</cameraName>
          <frameName>f651_brute/robot_camera_3rd</frameName>
          <CxPrime>640.5</CxPrime>
          <Cx>640.5</Cx>
          <Cy>360.5</Cy>
          <hackBaseline>0</hackBaseline>
          <focalLength>1004.603218</focalLength>
          <distortionK1>0.0</distortionK1>
          <distortionK2>0.0</distortionK2>
          <distortionK3>0.0</distortionK3>
          <distortionT1>0.0</distortionT1>
          <distortionT2>0.0</distortionT2>
          <robotNamespace>/</robotNamespace>
        </plugin>
      </sensor>

    </link>

	<joint name='camera_3rd_joint' type='fixed'>
        <parent>base_link</parent>
        <child>camera_3rd_link</child>
	</joint>

<!-- ########################################  /CAMERA 3rd  ######################################## -->

<!-- ##########################################  IMU  ############################################## -->
    <link name='imu_link'>
      <pose frame=''>0 0 0 0 0 3.1415927</pose>
      <inertial>
        <pose frame=''>0 0 0 0 -0 0</pose>
        <mass>0.015</mass>
        <inertia>
          <ixx>1e-05</ixx>
          <ixy>0</ixy>
          <ixz>0</ixz>
          <iyy>1e-05</iyy>
          <iyz>0</iyz>
          <izz>1e-05</izz>
        </inertia>
      </inertial>
    </link>

    <joint name='imu_joint' type='revolute'>
      <child>imu_link</child>
      <parent>base_link</parent>
      <axis>
        <xyz>1 0 0</xyz>
        <limit>
          <lower>0</lower>
          <upper>0</upper>
          <effort>0</effort>
          <velocity>0</velocity>
        </limit>
        <dynamics>
          <spring_reference>0</spring_reference>
          <spring_stiffness>0</spring_stiffness>
        </dynamics>
        <use_parent_model_frame>1</use_parent_model_frame>
      </axis>
    </joint>
<!-- #########################################  /IMU  ############################################## -->

<!-- #########################################  ROTOR0  ############################################ -->
<link name='rotor_0'>
      <pose frame=''>-0.279726205 0.1615 0.07 0 0 2.09439510239</pose>
      <inertial>
        <mass>0.005</mass>
        <inertia>
          <ixx>9.75e-07</ixx>
          <ixy>0</ixy>
          <ixz>0</ixz>
          <iyy>0.000273104</iyy>
          <iyz>0</iyz>
          <izz>0.000274004</izz>
        </inertia>
      </inertial>

<!--
	  <collision name='rotor_0_collision'>
        <geometry>
          <cylinder>
            <length>0.01</length>
            <radius>0.128</radius>
          </cylinder>
        </geometry>
        <surface>
          <contact>
            <ode/>
          </contact>
          <friction>
            <ode/>
          </friction>
        </surface>
      </collision>
-->

      <visual name='rotor_0_visual'>
        <geometry>
          <mesh>
            <scale>0.001 0.001 0.001</scale>
            <uri>model://f651_brute/meshes/prop_cw_CG.stl</uri>
          </mesh>
        </geometry>
        <material>
          <script>
            <name>Gazebo/DarkGrey</name>
            <uri>file://media/materials/scripts/gazebo.material</uri>
          </script>
        </material>
      </visual>
    </link>

    <joint name='rotor_0_joint' type='revolute'>
      <child>rotor_0</child>
      <parent>base_link</parent>
      <axis>
        <xyz>0.046 0.0827 1.8977</xyz>
        <limit>
          <lower>-1e+16</lower>
          <upper>1e+16</upper>
          <effort>10</effort>
          <velocity>-1</velocity>
        </limit>
        <dynamics>
          <damping>0.005</damping>
        </dynamics>
        <use_parent_model_frame>1</use_parent_model_frame>
      </axis>
      <physics>
        <ode>
          <implicit_spring_damper>1</implicit_spring_damper>
        </ode>
      </physics>
    </joint>
<!-- ########################################  /ROTOR0  ############################################ -->

<!-- #########################################  ROTOR1  ############################################ -->
<link name='rotor_1'>
      <pose frame=''>0.279726205 -0.1615 0.07 0 0 -2.09439510239</pose>
      <inertial>
        <mass>0.005</mass>
        <inertia>
          <ixx>9.75e-07</ixx>
          <ixy>0</ixy>
          <ixz>0</ixz>
          <iyy>0.000273104</iyy>
          <iyz>0</iyz>
          <izz>0.000274004</izz>
        </inertia>
      </inertial>

      <visual name='rotor_1_visual'>
        <geometry>
          <mesh>
            <scale>0.001 0.001 0.001</scale>
            <uri>model://f651_brute/meshes/prop_ccw_CG.stl</uri>
          </mesh>
        </geometry>
        <material>
          <script>
            <name>Gazebo/DarkGrey</name>
            <uri>file://media/materials/scripts/gazebo.material</uri>
          </script>
        </material>
      </visual>
    </link>

    <joint name='rotor_1_joint' type='revolute'>
      <child>rotor_1</child>
      <parent>base_link</parent>
      <axis>
        <xyz>0.046 0.0827 1.8977</xyz>
        <limit>
          <lower>-1e+16</lower>
          <upper>1e+16</upper>
          <effort>10</effort>
          <velocity>-1</velocity>
        </limit>
        <dynamics>
          <damping>0.005</damping>
        </dynamics>
        <use_parent_model_frame>1</use_parent_model_frame>
      </axis>
      <physics>
        <ode>
          <implicit_spring_damper>1</implicit_spring_damper>
        </ode>
      </physics>
    </joint>
<!-- ########################################  /ROTOR1  ############################################ -->

<!-- #########################################  ROTOR2  ############################################ -->
<link name='rotor_2'>
      <pose frame=''>-0.279726205 -0.1615 0.07 0 0 2.09439510239</pose>
      <inertial>
        <mass>0.005</mass>
        <inertia>
          <ixx>9.75e-07</ixx>
          <ixy>0</ixy>
          <ixz>0</ixz>
          <iyy>0.000273104</iyy>
          <iyz>0</iyz>
          <izz>0.000274004</izz>
        </inertia>
      </inertial>

      <visual name='rotor_2_visual'>
        <geometry>
          <mesh>
            <scale>0.001 0.001 0.001</scale>
            <uri>model://f550_amazing/meshes/prop_ccw_CG.stl</uri>
          </mesh>
        </geometry>
        <material>
          <script>
            <name>Gazebo/DarkGrey</name>
            <uri>file://media/materials/scripts/gazebo.material</uri>
          </script>
        </material>
      </visual>
    </link>

    <joint name='rotor_2_joint' type='revolute'>
      <child>rotor_2</child>
      <parent>base_link</parent>
      <axis>
        <xyz>0.046 0.0827 1.8977</xyz>
        <limit>
          <lower>-1e+16</lower>
          <upper>1e+16</upper>
          <effort>10</effort>
          <velocity>-1</velocity>
        </limit>
        <dynamics>
          <damping>0.005</damping>
        </dynamics>
        <use_parent_model_frame>1</use_parent_model_frame>
      </axis>
      <physics>
        <ode>
          <implicit_spring_damper>1</implicit_spring_damper>
        </ode>
      </physics>
    </joint>
<!-- ########################################  /ROTOR2  ############################################ -->

<!-- #########################################  ROTOR3  ############################################ -->
<link name='rotor_3'>
      <pose frame=''>0.279726205 0.1615 0.07 0 0 0</pose>
      <inertial>
        <mass>0.005</mass>
        <inertia>
          <ixx>9.75e-07</ixx>
          <ixy>0</ixy>
          <ixz>0</ixz>
          <iyy>0.000273104</iyy>
          <iyz>0</iyz>
          <izz>0.000274004</izz>
        </inertia>
      </inertial>

      <visual name='rotor_3_visual'>
        <geometry>
          <mesh>
            <scale>0.001 0.001 0.001</scale>
            <uri>model://f550_amazing/meshes/prop_cw_CG.stl</uri>
          </mesh>
        </geometry>
        <material>
          <script>
            <name>Gazebo/DarkGrey</name>
            <uri>file://media/materials/scripts/gazebo.material</uri>
          </script>
        </material>
      </visual>
    </link>

    <joint name='rotor_3_joint' type='revolute'>
      <child>rotor_3</child>
      <parent>base_link</parent>
      <axis>
        <xyz>0.046 0.0827 1.8977</xyz>
        <limit>
          <lower>-1e+16</lower>
          <upper>1e+16</upper>
          <effort>10</effort>
          <velocity>-1</velocity>
        </limit>
        <dynamics>
          <damping>0.005</damping>
        </dynamics>
        <use_parent_model_frame>1</use_parent_model_frame>
      </axis>
      <physics>
        <ode>
          <implicit_spring_damper>1</implicit_spring_damper>
        </ode>
      </physics>
    </joint>
<!-- ########################################  /ROTOR3  ############################################ -->

<!-- #########################################  ROTOR4  ############################################ -->
<link name='rotor_4'>
      <pose frame=''>0 0.323 0.07 0 0 0</pose>
      <inertial>
        <mass>0.005</mass>
        <inertia>
          <ixx>9.75e-07</ixx>
          <ixy>0</ixy>
          <ixz>0</ixz>
          <iyy>0.000273104</iyy>
          <iyz>0</iyz>
          <izz>0.000274004</izz>
        </inertia>
      </inertial>

      <visual name='rotor_4_visual'>
        <geometry>
          <mesh>
            <scale>0.001 0.001 0.001</scale>
            <uri>model://f550_amazing/meshes/prop_ccw_CG.stl</uri>
          </mesh>
        </geometry>
        <material>
          <script>
            <name>Gazebo/DarkGrey</name>
            <uri>file://media/materials/scripts/gazebo.material</uri>
          </script>
        </material>
      </visual>
    </link>

    <joint name='rotor_4_joint' type='revolute'>
      <child>rotor_4</child>
      <parent>base_link</parent>
      <axis>
        <xyz>0.046 0.0827 1.8977</xyz>
        <limit>
          <lower>-1e+16</lower>
          <upper>1e+16</upper>
          <effort>10</effort>
          <velocity>-1</velocity>
        </limit>
        <dynamics>
          <damping>0.005</damping>
        </dynamics>
        <use_parent_model_frame>1</use_parent_model_frame>
      </axis>
      <physics>
        <ode>
          <implicit_spring_damper>1</implicit_spring_damper>
        </ode>
      </physics>
    </joint>
<!-- ########################################  /ROTOR4  ############################################ -->

<!-- #########################################  ROTOR5  ############################################ -->
<link name='rotor_5'>
      <pose frame=''>0 -0.323 0.07 0 0 -2.09439510239</pose>
      <inertial>
        <mass>0.005</mass>
        <inertia>
          <ixx>9.75e-07</ixx>
          <ixy>0</ixy>
          <ixz>0</ixz>
          <iyy>0.000273104</iyy>
          <iyz>0</iyz>
          <izz>0.000274004</izz>
        </inertia>
      </inertial>

      <visual name='rotor_5_visual'>
        <geometry>
          <mesh>
            <scale>0.001 0.001 0.001</scale>
            <uri>model://f550_amazing/meshes/prop_ccw_CG.stl</uri>
          </mesh>
        </geometry>
        <material>
          <script>
            <name>Gazebo/DarkGrey</name>
            <uri>file://media/materials/scripts/gazebo.material</uri>
          </script>
        </material>
      </visual>
    </link>

    <joint name='rotor_5_joint' type='revolute'>
      <child>rotor_5</child>
      <parent>base_link</parent>
      <axis>
        <xyz>0.046 0.0827 1.8977</xyz>
        <limit>
          <lower>-1e+16</lower>
          <upper>1e+16</upper>
          <effort>10</effort>
          <velocity>-1</velocity>
        </limit>
        <dynamics>
          <damping>0.005</damping>
        </dynamics>
        <use_parent_model_frame>1</use_parent_model_frame>
      </axis>
      <physics>
        <ode>
          <implicit_spring_damper>1</implicit_spring_damper>
        </ode>
      </physics>
    </joint>
<!-- ########################################  /ROTOR5  ############################################ -->

<!-- #####################################  MOTOR PLUGINS  ######################################### -->
    <plugin name='front_right_motor_model' filename='librotors_gazebo_motor_model.so'>
      <robotNamespace></robotNamespace>
      <jointName>rotor_0_joint</jointName>
      <linkName>rotor_0</linkName>
      <turningDirection>ccw</turningDirection>
      <timeConstantUp>0.0125</timeConstantUp>
      <timeConstantDown>0.025</timeConstantDown>
      <maxRotVelocity>1100</maxRotVelocity>
      <motorConstant>8.54858e-06</motorConstant>
      <momentConstant>0.06</momentConstant>
      <commandSubTopic>/gazebo/command/motor_speed</commandSubTopic>
      <motorNumber>4</motorNumber>
      <rotorDragCoefficient>0.000806428</rotorDragCoefficient>
      <rollingMomentCoefficient>1e-06</rollingMomentCoefficient>
      <motorSpeedPubTopic>/motor_speed/4</motorSpeedPubTopic>
      <rotorVelocitySlowdownSim>10</rotorVelocitySlowdownSim>
    </plugin>

    <plugin name='back_left_motor_model' filename='librotors_gazebo_motor_model.so'>
      <robotNamespace></robotNamespace>
      <jointName>rotor_1_joint</jointName>
      <linkName>rotor_1</linkName>
      <turningDirection>cw</turningDirection>
      <timeConstantUp>0.0125</timeConstantUp>
      <timeConstantDown>0.025</timeConstantDown>
      <maxRotVelocity>1100</maxRotVelocity>
      <motorConstant>8.54858e-06</motorConstant>
      <momentConstant>0.06</momentConstant>
      <commandSubTopic>/gazebo/command/motor_speed</commandSubTopic>
      <motorNumber>5</motorNumber>
      <rotorDragCoefficient>0.000806428</rotorDragCoefficient>
      <rollingMomentCoefficient>1e-06</rollingMomentCoefficient>
      <motorSpeedPubTopic>/motor_speed/5</motorSpeedPubTopic>
      <rotorVelocitySlowdownSim>10</rotorVelocitySlowdownSim>
    </plugin>

    <plugin name='front_left_motor_model' filename='librotors_gazebo_motor_model.so'>
      <robotNamespace></robotNamespace>
      <jointName>rotor_2_joint</jointName>
      <linkName>rotor_2</linkName>
      <turningDirection>cw</turningDirection>
      <timeConstantUp>0.0125</timeConstantUp>
      <timeConstantDown>0.025</timeConstantDown>
      <maxRotVelocity>1100</maxRotVelocity>
      <motorConstant>8.54858e-06</motorConstant>
      <momentConstant>0.06</momentConstant>
      <commandSubTopic>/gazebo/command/motor_speed</commandSubTopic>
      <motorNumber>2</motorNumber>
      <rotorDragCoefficient>0.000806428</rotorDragCoefficient>
      <rollingMomentCoefficient>1e-06</rollingMomentCoefficient>
      <motorSpeedPubTopic>/motor_speed/2</motorSpeedPubTopic>
      <rotorVelocitySlowdownSim>10</rotorVelocitySlowdownSim>
    </plugin>

    <plugin name='back_right_motor_model' filename='librotors_gazebo_motor_model.so'>
      <robotNamespace></robotNamespace>
      <jointName>rotor_3_joint</jointName>
      <linkName>rotor_3</linkName>
      <turningDirection>ccw</turningDirection>
      <timeConstantUp>0.0125</timeConstantUp>
      <timeConstantDown>0.025</timeConstantDown>
      <maxRotVelocity>1100</maxRotVelocity>
      <motorConstant>8.54858e-06</motorConstant>
      <momentConstant>0.06</momentConstant>
      <commandSubTopic>/gazebo/command/motor_speed</commandSubTopic>
      <motorNumber>3</motorNumber>
      <rotorDragCoefficient>0.000806428</rotorDragCoefficient>
      <rollingMomentCoefficient>1e-06</rollingMomentCoefficient>
      <motorSpeedPubTopic>/motor_speed/3</motorSpeedPubTopic>
      <rotorVelocitySlowdownSim>10</rotorVelocitySlowdownSim>
    </plugin>

    <plugin name='back_left_motor_model' filename='librotors_gazebo_motor_model.so'>
      <robotNamespace></robotNamespace>
      <jointName>rotor_4_joint</jointName>
      <linkName>rotor_4</linkName>
      <turningDirection>cw</turningDirection>
      <timeConstantUp>0.0125</timeConstantUp>
      <timeConstantDown>0.025</timeConstantDown>
      <maxRotVelocity>1100</maxRotVelocity>
      <motorConstant>8.54858e-06</motorConstant>
      <momentConstant>0.06</momentConstant>
      <commandSubTopic>/gazebo/command/motor_speed</commandSubTopic>
      <motorNumber>0</motorNumber>
      <rotorDragCoefficient>0.000806428</rotorDragCoefficient>
      <rollingMomentCoefficient>1e-06</rollingMomentCoefficient>
      <motorSpeedPubTopic>/motor_speed/0</motorSpeedPubTopic>
      <rotorVelocitySlowdownSim>10</rotorVelocitySlowdownSim>
    </plugin>

    <plugin name='front_left_motor_model' filename='librotors_gazebo_motor_model.so'>
      <robotNamespace></robotNamespace>
      <jointName>rotor_5_joint</jointName>
      <linkName>rotor_5</linkName>
      <turningDirection>ccw</turningDirection>
      <timeConstantUp>0.0125</timeConstantUp>
      <timeConstantDown>0.025</timeConstantDown>
      <maxRotVelocity>1100</maxRotVelocity>
      <motorConstant>8.54858e-06</motorConstant>
      <momentConstant>0.06</momentConstant>
      <commandSubTopic>/gazebo/command/motor_speed</commandSubTopic>
      <motorNumber>1</motorNumber>
      <rotorDragCoefficient>0.000806428</rotorDragCoefficient>
      <rollingMomentCoefficient>1e-06</rollingMomentCoefficient>
      <motorSpeedPubTopic>/motor_speed/1</motorSpeedPubTopic>
      <rotorVelocitySlowdownSim>10</rotorVelocitySlowdownSim>
    </plugin>
<!-- ####################################  /MOTOR PLUGINS  ######################################### -->

<!-- ###################################  MAVLINK PLUGIN  ########################################## -->
    <plugin name='mavlink_interface' filename='librotors_gazebo_mavlink_interface.so'>
      <robotNamespace></robotNamespace>
      <imuSubTopic>/imu</imuSubTopic>
      <motorSpeedCommandPubTopic>/gazebo/command/motor_speed</motorSpeedCommandPubTopic>
      <control_channels>

        <channel name="rotor0">
          <input_index>0</input_index>
          <input_offset>1</input_offset>
          <input_scaling>450</input_scaling>
          <zero_position_disarmed>0</zero_position_disarmed>
          <zero_position_armed>100</zero_position_armed>
          <joint_control_type>velocity</joint_control_type>
          <joint_name>rotor_4_joint</joint_name>
        </channel>

        <channel name="rotor1">
          <input_index>1</input_index>
          <input_offset>1</input_offset>
          <input_scaling>450</input_scaling>
          <zero_position_disarmed>0</zero_position_disarmed>
          <zero_position_armed>100</zero_position_armed>
          <joint_control_type>velocity</joint_control_type>

          <joint_name>rotor_5_joint</joint_name>
        </channel>

        <channel name="rotor2">
          <input_index>2</input_index>
          <input_offset>1</input_offset>
          <input_scaling>450</input_scaling>
          <zero_position_disarmed>0</zero_position_disarmed>
          <zero_position_armed>100</zero_position_armed>
          <joint_control_type>velocity</joint_control_type>
          <joint_name>rotor_2_joint</joint_name>
        </channel>

        <channel name="rotor3">
          <input_index>3</input_index>
          <input_offset>1</input_offset>
          <input_scaling>450</input_scaling>
          <zero_position_disarmed>0</zero_position_disarmed>
          <zero_position_armed>100</zero_position_armed>
          <joint_control_type>velocity</joint_control_type>
          <joint_name>rotor_3_joint</joint_name>
        </channel>

        <channel name="rotor4">
          <input_index>4</input_index>
          <input_offset>1</input_offset>
          <input_scaling>450</input_scaling>
          <zero_position_disarmed>0</zero_position_disarmed>
          <zero_position_armed>100</zero_position_armed>
          <joint_control_type>velocity</joint_control_type>
          <joint_name>rotor_0_joint</joint_name>
        </channel>

        <channel name="rotor5">
          <input_index>5</input_index>
          <input_offset>1</input_offset>
          <input_scaling>450</input_scaling>
          <zero_position_disarmed>0</zero_position_disarmed>
          <zero_position_armed>100</zero_position_armed>
          <joint_control_type>velocity</joint_control_type>
          <joint_name>rotor_1_joint</joint_name>
        </channel>

        <channel name="gimbal_roll">
          <input_index>6</input_index>
          <input_offset>0</input_offset>
          <input_scaling>-3.1415</input_scaling>
          <zero_position_disarmed>0</zero_position_disarmed>
          <zero_position_armed>0</zero_position_armed>
          <joint_control_type>position_gztopic</joint_control_type>
          <gztopic>/gimbal_roll_cmd</gztopic>
          <joint_name>typhoon_h480::cgo3_camera_joint</joint_name>
        </channel>

        <channel name="gimbal_pitch">
          <input_index>7</input_index>
          <input_offset>0</input_offset>
          <input_scaling>3.1415</input_scaling>
          <zero_position_disarmed>0</zero_position_disarmed>
          <zero_position_armed>0</zero_position_armed>
          <joint_control_type>position_gztopic</joint_control_type>
          <gztopic>/gimbal_pitch_cmd</gztopic>
          <joint_name>typhoon_h480::cgo3_camera_joint</joint_name>
        </channel>

        <channel name="gimbal_yaw">
          <input_index>8</input_index>
          <input_offset>-0.5</input_offset>
          <input_scaling>-3.1415</input_scaling>
          <zero_position_disarmed>0</zero_position_disarmed>
          <zero_position_armed>0</zero_position_armed>
          <joint_control_type>position_gztopic</joint_control_type>
          <gztopic>/gimbal_yaw_cmd</gztopic>
          <joint_name>typhoon_h480::cgo3_vertical_arm_joint</joint_name>
        </channel>

        <channel name="left_leg">
          <input_index>9</input_index>
          <input_offset>1</input_offset>
          <input_scaling>1</input_scaling>
          <zero_position_disarmed>0</zero_position_disarmed>
          <zero_position_armed>0</zero_position_armed>
          <joint_control_type>position</joint_control_type>
          <joint_control_pid>
            <p>50.0</p>
            <i>0</i>
            <d>0</d>
            <iMax>0</iMax>
            <iMin>0</iMin>
            <cmdMax>10</cmdMax>
            <cmdMin>-10</cmdMin>
          </joint_control_pid>
          <joint_name>left_leg_joint</joint_name>
        </channel>

        <channel name="right_leg">
          <input_index>10</input_index>
          <input_offset>1</input_offset>
          <input_scaling>1</input_scaling>
          <zero_position_disarmed>0</zero_position_disarmed>
          <zero_position_armed>0</zero_position_armed>
          <joint_control_type>position</joint_control_type>
          <joint_control_pid>
            <p>50.0</p>
            <i>0</i>
            <d>0</d>
            <iMax>0</iMax>
            <iMin>0</iMin>
            <cmdMax>10</cmdMax>
            <cmdMin>-10</cmdMin>
          </joint_control_pid>
          <joint_name>right_leg_joint</joint_name>
        </channel>
      </control_channels>
    </plugin>

<!-- ###################################  /MAVLINK PLUGIN  ######################################### -->

<!-- ###################################  IMU PLUGIN  ############################################## -->
    <plugin name='rotors_gazebo_imu_plugin' filename='librotors_gazebo_imu_plugin.so'>
      <robotNamespace></robotNamespace>
      <linkName>imu_link</linkName>
      <imuTopic>/imu</imuTopic>
      <gyroscopeNoiseDensity>0</gyroscopeNoiseDensity>
      <gyroscopeRandomWalk>0</gyroscopeRandomWalk>
      <gyroscopeBiasCorrelationTime>1000.0</gyroscopeBiasCorrelationTime>
      <gyroscopeTurnOnBiasSigma>0</gyroscopeTurnOnBiasSigma>
      <accelerometerNoiseDensity>0</accelerometerNoiseDensity>
      <accelerometerRandomWalk>0</accelerometerRandomWalk>
      <accelerometerBiasCorrelationTime>300.0</accelerometerBiasCorrelationTime>
      <accelerometerTurnOnBiasSigma>0</accelerometerTurnOnBiasSigma>
    </plugin>
<!-- ##################################  /IMU PLUGIN  ############################################## -->

  </model>
</sdf>
